Workbook

Sheet Read me
A1: IEEE journals — open-access model, APC 2026 and time to first decision
A2: • Hybrid = subscription journal. Publishing is FREE unless you choose open access (then you pay the APC). Overlength page charges may still apply.
A3: • Fully open access = every accepted article pays the APC. There is no free option (waivers exist for low-income countries).
A4: • APCs are formulas that read the 'Pricing rules' sheet — change a blue cell there and every journal updates. A few titles have their own price (set in the data).
A5: • Decision times: IEEE does not publish a time to first decision for most journals. Figures appear only where an IEEE society or a named source gives one; the source type is shown next to it.
A6: • Red notes: open-access model not confirmed in 2026 sources — check the journal's author page.
A7: Generated from data/journals.yml in github.com/aionndc22/ieee-conference-deadlines — contributions welcome. Not affiliated with IEEE.

Sheet Pricing rules
A1: IEEE open-access pricing — 2026 submissions (last checked 2026-10-16)
A2: Blue cells are inputs; the Journals sheet recalculates from them.
A3: Publishing model | B3: APC 2026 (US$) | C3: If you don't choose open access | D3: What it means
A4: Hybrid | B4: 2800 | C4: Free (overlength page charges may apply) | D4: Subscription journal. Publishing is free unless you choose open access; mandatory overlength page charges may apply.
A5: Fully open access | B5: 2160 | C5: Not available — OA only | D5: Gold open access: every accepted article pays the APC. Standard rate for most fully OA titles; a few titles differ.
A6: Hybrid magazine | B6: 2995 | C6: Free (most articles are invited) | D6: Magazine with an optional open-access fee (most magazines).
A8: Discounts
A9: IEEE member discount | B9: 0.05
A10: IEEE Society member discount | B10: 0.2 | C10: Discounts do not stack; students excluded.
A12: Sources
A13: https://open.ieee.org/for-authors/article-processing-charges/
A14: https://journals.ieeeauthorcenter.ieee.org/wp-content/uploads/sites/7/2026-07-30-IEEE-Article-Processing-Charges-List.pdf
A15: https://ieee-aess.org/apc-open-access
A16: https://open.ieee.org/for-authors/ieee-low-and-lower-middle-income-country-open-access-discount-program/

Sheet Summary by track
A1: IEEE journals by track — counts by publishing model
A3: Track | B3: Journals | C3: Hybrid | D3: Fully open access | E3: With a decision-time figure
A4: Aerospace, Radar & Navigation | B4: =COUNTIF(Journals!$A$2:$A$175,A4) | C4: =COUNTIFS(Journals!$A$2:$A$175,A4,Journals!$E$2:$E$175,"Hybrid") | D4: =COUNTIFS(Journals!$A$2:$A$175,A4,Journals!$E$2:$E$175,"Fully open access") | E4: =COUNTIFS(Journals!$A$2:$A$175,A4,Journals!$I$2:$I$175,"<>Not published")
A5: Communications & Networking | B5: =COUNTIF(Journals!$A$2:$A$175,A5) | C5: =COUNTIFS(Journals!$A$2:$A$175,A5,Journals!$E$2:$E$175,"Hybrid") | D5: =COUNTIFS(Journals!$A$2:$A$175,A5,Journals!$E$2:$E$175,"Fully open access") | E5: =COUNTIFS(Journals!$A$2:$A$175,A5,Journals!$I$2:$I$175,"<>Not published")
A6: Signal, Image & Speech Processing | B6: =COUNTIF(Journals!$A$2:$A$175,A6) | C6: =COUNTIFS(Journals!$A$2:$A$175,A6,Journals!$E$2:$E$175,"Hybrid") | D6: =COUNTIFS(Journals!$A$2:$A$175,A6,Journals!$E$2:$E$175,"Fully open access") | E6: =COUNTIFS(Journals!$A$2:$A$175,A6,Journals!$I$2:$I$175,"<>Not published")
A7: AI, Computing & Software | B7: =COUNTIF(Journals!$A$2:$A$175,A7) | C7: =COUNTIFS(Journals!$A$2:$A$175,A7,Journals!$E$2:$E$175,"Hybrid") | D7: =COUNTIFS(Journals!$A$2:$A$175,A7,Journals!$E$2:$E$175,"Fully open access") | E7: =COUNTIFS(Journals!$A$2:$A$175,A7,Journals!$I$2:$I$175,"<>Not published")
A8: Antennas, Microwaves & EM | B8: =COUNTIF(Journals!$A$2:$A$175,A8) | C8: =COUNTIFS(Journals!$A$2:$A$175,A8,Journals!$E$2:$E$175,"Hybrid") | D8: =COUNTIFS(Journals!$A$2:$A$175,A8,Journals!$E$2:$E$175,"Fully open access") | E8: =COUNTIFS(Journals!$A$2:$A$175,A8,Journals!$I$2:$I$175,"<>Not published")
A9: Photonics, Quantum & Plasma | B9: =COUNTIF(Journals!$A$2:$A$175,A9) | C9: =COUNTIFS(Journals!$A$2:$A$175,A9,Journals!$E$2:$E$175,"Hybrid") | D9: =COUNTIFS(Journals!$A$2:$A$175,A9,Journals!$E$2:$E$175,"Fully open access") | E9: =COUNTIFS(Journals!$A$2:$A$175,A9,Journals!$I$2:$I$175,"<>Not published")
A10: Geoscience, Remote Sensing & Ocean | B10: =COUNTIF(Journals!$A$2:$A$175,A10) | C10: =COUNTIFS(Journals!$A$2:$A$175,A10,Journals!$E$2:$E$175,"Hybrid") | D10: =COUNTIFS(Journals!$A$2:$A$175,A10,Journals!$E$2:$E$175,"Fully open access") | E10: =COUNTIFS(Journals!$A$2:$A$175,A10,Journals!$I$2:$I$175,"<>Not published")
A11: Circuits, Devices & Semiconductors | B11: =COUNTIF(Journals!$A$2:$A$175,A11) | C11: =COUNTIFS(Journals!$A$2:$A$175,A11,Journals!$E$2:$E$175,"Hybrid") | D11: =COUNTIFS(Journals!$A$2:$A$175,A11,Journals!$E$2:$E$175,"Fully open access") | E11: =COUNTIFS(Journals!$A$2:$A$175,A11,Journals!$I$2:$I$175,"<>Not published")
A12: Power, Energy & Industrial Electronics | B12: =COUNTIF(Journals!$A$2:$A$175,A12) | C12: =COUNTIFS(Journals!$A$2:$A$175,A12,Journals!$E$2:$E$175,"Hybrid") | D12: =COUNTIFS(Journals!$A$2:$A$175,A12,Journals!$E$2:$E$175,"Fully open access") | E12: =COUNTIFS(Journals!$A$2:$A$175,A12,Journals!$I$2:$I$175,"<>Not published")
A13: Control, Robotics & Systems | B13: =COUNTIF(Journals!$A$2:$A$175,A13) | C13: =COUNTIFS(Journals!$A$2:$A$175,A13,Journals!$E$2:$E$175,"Hybrid") | D13: =COUNTIFS(Journals!$A$2:$A$175,A13,Journals!$E$2:$E$175,"Fully open access") | E13: =COUNTIFS(Journals!$A$2:$A$175,A13,Journals!$I$2:$I$175,"<>Not published")
A14: Vehicles & Transportation | B14: =COUNTIF(Journals!$A$2:$A$175,A14) | C14: =COUNTIFS(Journals!$A$2:$A$175,A14,Journals!$E$2:$E$175,"Hybrid") | D14: =COUNTIFS(Journals!$A$2:$A$175,A14,Journals!$E$2:$E$175,"Fully open access") | E14: =COUNTIFS(Journals!$A$2:$A$175,A14,Journals!$I$2:$I$175,"<>Not published")
A15: Instrumentation, Sensors & Measurement | B15: =COUNTIF(Journals!$A$2:$A$175,A15) | C15: =COUNTIFS(Journals!$A$2:$A$175,A15,Journals!$E$2:$E$175,"Hybrid") | D15: =COUNTIFS(Journals!$A$2:$A$175,A15,Journals!$E$2:$E$175,"Fully open access") | E15: =COUNTIFS(Journals!$A$2:$A$175,A15,Journals!$I$2:$I$175,"<>Not published")
... A17: Multidisciplinary, Education & Society | B17: =COUNTIF(Journals!$A$2:$A$175,A17) | C17: =COUNTIFS(Journals!$A$2:$A$175,A17,Journals!$E$2:$E$175,"Hybrid") | D17: =COUNTIFS(Journals!$A$2:$A$175,A17,Journals!$E$2:$E$175,"Fully open access") | E17: =COUNTIFS(Journals!$A$2:$A$175,A17,Journals!$I$2:$I$175,"<>Not published")
A18: Total | B18: =SUM(B4:B17) | C18: =SUM(C4:C17) | D18: =SUM(D4:D17) | E18: =SUM(E4:E17)

Sheet Journals
A1: Track | B1: Journal | C1: Acronym | D1: Type | E1: OA model | F1: APC 2026 (US$) | G1: APC for society member (US$) | H1: Cost without OA | I1: Avg. time to first decision | J1: Decision-time source | K1: Source link | L1: Society | M1: Notes
A2: Aerospace, Radar & Navigation | B2: IEEE Transactions on Aerospace and Electronic Systems | C2: TAES | D2: Transactions | E2: Hybrid | F2: =INDEX('Pricing rules'!$B$4:$B$6,MATCH(E2,'Pricing rules'!$A$4:$A$6,0)) | G2: =ROUND(F2*(1-'Pricing rules'!$B$10),0) | H2: Free (overlength page charges may apply) | I2: ~22.6 weeks first review round | J2: Crowd-sourced (SciRev) | K2: https://scirev.org/journal/ieee-transactions-on-aerospace-and-electronic-systems/ | L2: AESS | M2: AESS flagship. APC US$2,800 confirmed by AESS for 2026.
A3: Aerospace, Radar & Navigation | B3: IEEE Transactions on Radar Systems | C3: T-RS | D3: Transactions | E3: Hybrid | F3: =INDEX('Pricing rules'!$B$4:$B$6,MATCH(E3,'Pricing rules'!$A$4:$A$6,0)) | G3: =ROUND(F3*(1-'Pricing rules'!$B$10),0) | H3: Free (overlength page charges may apply) | I3: Not published | L3: AESS | M3: Open-access model not confirmed for 2026 — check the journal's author page.
A4: Aerospace, Radar & Navigation | B4: IEEE Journal on Miniaturization for Air and Space Systems | C4: J-MASS | D4: Journal | E4: Hybrid | F4: =INDEX('Pricing rules'!$B$4:$B$6,MATCH(E4,'Pricing rules'!$A$4:$A$6,0)) | G4: =ROUND(F4*(1-'Pricing rules'!$B$10),0) | H4: Free (overlength page charges may apply) | I4: Not published | L4: AESS | M4: Open-access model not confirmed for 2026 — check the journal's author page.
A5: Aerospace, Radar & Navigation | B5: IEEE Journal of Indoor and Seamless Positioning and Navigation | C5: J-ISPIN | D5: Journal | E5: Fully open access | F5: =INDEX('Pricing rules'!$B$4:$B$6,MATCH(E5,'Pricing rules'!$A$4:$A$6,0)) | G5: =ROUND(F5*(1-'Pricing rules'!$B$10),0) | H5: Not available — OA only | I5: Not published | M5: Gold OA (IEEE Sensors Council, SPS, IMS).
A6: Aerospace, Radar & Navigation | B6: IEEE Journal of Radio Frequency Identification | C6: JRFID | D6: Journal | E6: Hybrid | F6: =INDEX('Pricing rules'!$B$4:$B$6,MATCH(E6,'Pricing rules'!$A$4:$A$6,0)) | G6: =ROUND(F6*(1-'Pricing rules'!$B$10),0) | H6: Free (overlength page charges may apply) | I6: Not published | M6: Open-access model not confirmed for 2026 — check the journal's author page.
A7: Communications & Networking | B7: IEEE Journal on Selected Areas in Communications | C7: JSAC | D7: Journal | E7: Hybrid | F7: =INDEX('Pricing rules'!$B$4:$B$6,MATCH(E7,'Pricing rules'!$A$4:$A$6,0)) | G7: =ROUND(F7*(1-'Pricing rules'!$B$10),0) | H7: Free (overlength page charges may apply) | I7: 4–8 months to first decision | J7: Third-party estimate | K7: https://manusights.com/blog/average-review-times-100-journals-2026 | M7: Special-issue driven.
A8: Communications & Networking | B8: IEEE Transactions on Communications | C8: TCOM | D8: Transactions | E8: Hybrid | F8: =INDEX('Pricing rules'!$B$4:$B$6,MATCH(E8,'Pricing rules'!$A$4:$A$6,0)) | G8: =ROUND(F8*(1-'Pricing rules'!$B$10),0) | H8: Free (overlength page charges may apply) | I8: 3–5 months to first decision | J8: Third-party estimate | K8: https://manusights.com/blog/average-review-times-100-journals-2026
A9: Communications & Networking | B9: IEEE Transactions on Wireless Communications | C9: TWC | D9: Transactions | E9: Hybrid | F9: =INDEX('Pricing rules'!$B$4:$B$6,MATCH(E9,'Pricing rules'!$A$4:$A$6,0)) | G9: =ROUND(F9*(1-'Pricing rules'!$B$10),0) | H9: Free (overlength page charges may apply) | I9: 3–5 months to first decision (sources conflict) | J9: Third-party estimate | K9: https://manusights.com/blog/ieee-transactions-on-wireless-communications-submission-guide
A10: Communications & Networking | B10: IEEE Communications Letters | C10: COMML | D10: Letters | E10: Hybrid | F10: =INDEX('Pricing rules'!$B$4:$B$6,MATCH(E10,'Pricing rules'!$A$4:$A$6,0)) | G10: =ROUND(F10*(1-'Pricing rules'!$B$10),0) | H10: Free (overlength page charges may apply) | I10: Not published
A11: Communications & Networking | B11: IEEE Wireless Communications Letters | C11: WCL | D11: Letters | E11: Hybrid | F11: =INDEX('Pricing rules'!$B$4:$B$6,MATCH(E11,'Pricing rules'!$A$4:$A$6,0)) | G11: =ROUND(F11*(1-'Pricing rules'!$B$10),0) | H11: Free (overlength page charges may apply) | I11: Not published
A12: Communications & Networking | B12: IEEE Communications Surveys & Tutorials | C12: COMST | D12: Journal | E12: Hybrid | F12: =INDEX('Pricing rules'!$B$4:$B$6,MATCH(E12,'Pricing rules'!$A$4:$A$6,0)) | G12: =ROUND(F12*(1-'Pricing rules'!$B$10),0) | H12: Free (overlength page charges may apply) | I12: Not published | M12: Surveys/tutorials only.
A13: Communications & Networking | B13: IEEE Transactions on Networking (formerly IEEE/ACM ToN) | C13: ToN | D13: Transactions | E13: Hybrid | F13: =INDEX('Pricing rules'!$B$4:$B$6,MATCH(E13,'Pricing rules'!$A$4:$A$6,0)) | G13: =ROUND(F13*(1-'Pricing rules'!$B$10),0) | H13: Free (overlength page charges may apply) | I13: ~5 months (editor assignment to first decision) | J13: Official (IEEE ComSoc) | K13: https://www.comsoc.org/publications/journals/ieee-tnet/policies-guidelines
A14: Communications & Networking | B14: IEEE Transactions on Network and Service Management | C14: TNSM | D14: Transactions | E14: Hybrid | F14: =INDEX('Pricing rules'!$B$4:$B$6,MATCH(E14,'Pricing rules'!$A$4:$A$6,0)) | G14: =ROUND(F14*(1-'Pricing rules'!$B$10),0) | H14: Free (overlength page charges may apply) | I14: Not published
A15: Communications & Networking | B15: IEEE Transactions on Cognitive Communications and Networking | C15: TCCN | D15: Transactions | E15: Hybrid | F15: =INDEX('Pricing rules'!$B$4:$B$6,MATCH(E15,'Pricing rules'!$A$4:$A$6,0)) | G15: =ROUND(F15*(1-'Pricing rules'!$B$10),0) | H15: Free (overlength page charges may apply) | I15: Not published
A16: Communications & Networking | B16: IEEE Transactions on Green Communications and Networking | C16: TGCN | D16: Transactions | E16: Hybrid | F16: =INDEX('Pricing rules'!$B$4:$B$6,MATCH(E16,'Pricing rules'!$A$4:$A$6,0)) | G16: =ROUND(F16*(1-'Pricing rules'!$B$10),0) | H16: Free (overlength page charges may apply) | I16: Not published
A17: Communications & Networking | B17: IEEE Transactions on Mobile Computing | C17: TMC | D17: Transactions | E17: Hybrid | F17: =INDEX('Pricing rules'!$B$4:$B$6,MATCH(E17,'Pricing rules'!$A$4:$A$6,0)) | G17: =ROUND(F17*(1-'Pricing rules'!$B$10),0) | H17: Free (overlength page charges may apply) | I17: Not published
A18: Communications & Networking | B18: IEEE Internet of Things Journal | C18: IoT-J | D18: Journal | E18: Hybrid | F18: =INDEX('Pricing rules'!$B$4:$B$6,MATCH(E18,'Pricing rules'!$A$4:$A$6,0)) | G18: =ROUND(F18*(1-'Pricing rules'!$B$10),0) | H18: Free (overlength page charges may apply) | I18: ~6.9 weeks to first decision | J18: Third-party estimate | K18: https://manusights.com/blog/ieee-internet-of-things-journal-submission-guide
A19: Communications & Networking | B19: IEEE Transactions on Network Science and Engineering | C19: TNSE | D19: Transactions | E19: Hybrid | F19: =INDEX('Pricing rules'!$B$4:$B$6,MATCH(E19,'Pricing rules'!$A$4:$A$6,0)) | G19: =ROUND(F19*(1-'Pricing rules'!$B$10),0) | H19: Free (overlength page charges may apply) | I19: Not published
A20: Communications & Networking | B20: IEEE Transactions on Molecular, Biological, and Multi-Scale Communications | C20: TMBMC | D20: Transactions | E20: Hybrid | F20: =INDEX('Pricing rules'!$B$4:$B$6,MATCH(E20,'Pricing rules'!$A$4:$A$6,0)) | G20: =ROUND(F20*(1-'Pricing rules'!$B$10),0) | H20: Free (overlength page charges may apply) | I20: Not published
A21: Communications & Networking | B21: IEEE Transactions on Machine Learning in Communications and Networking | C21: TMLCN | D21: Transactions | E21: Fully open access | F21: =INDEX('Pricing rules'!$B$4:$B$6,MATCH(E21,'Pricing rules'!$A$4:$A$6,0)) | G21: =ROUND(F21*(1-'Pricing rules'!$B$10),0) | H21: Not available — OA only | I21: Not published | M21: Open-access model not confirmed for 2026 — check the journal's author page.
A22: Communications & Networking | B22: IEEE Networking Letters | C22: LNET | D22: Letters | E22: Hybrid | F22: =INDEX('Pricing rules'!$B$4:$B$6,MATCH(E22,'Pricing rules'!$A$4:$A$6,0)) | G22: =ROUND(F22*(1-'Pricing rules'!$B$10),0) | H22: Free (overlength page charges may apply) | I22: Not published
A23: Communications & Networking | B23: IEEE Transactions on Broadcasting | C23: TBC | D23: Transactions | E23: Hybrid | F23: =INDEX('Pricing rules'!$B$4:$B$6,MATCH(E23,'Pricing rules'!$A$4:$A$6,0)) | G23: =ROUND(F23*(1-'Pricing rules'!$B$10),0) | H23: Free (overlength page charges may apply) | I23: Not published
A24: Communications & Networking | B24: IEEE Transactions on Information Theory | C24: TIT | D24: Transactions | E24: Hybrid | F24: =INDEX('Pricing rules'!$B$4:$B$6,MATCH(E24,'Pricing rules'!$A$4:$A$6,0)) | G24: =ROUND(F24*(1-'Pricing rules'!$B$10),0) | H24: Free (overlength page charges may apply) | I24: Not published
A25: Communications & Networking | B25: IEEE Journal on Selected Areas in Information Theory | C25: JSAIT | D25: Journal | E25: Hybrid | F25: =INDEX('Pricing rules'!$B$4:$B$6,MATCH(E25,'Pricing rules'!$A$4:$A$6,0)) | G25: =ROUND(F25*(1-'Pricing rules'!$B$10),0) | H25: Free (overlength page charges may apply) | I25: Not published | M25: Open-access model not confirmed for 2026 — check the journal's author page.
A26: Communications & Networking | B26: IEEE Open Journal of the Communications Society | C26: OJ-COMS | D26: Open journal | E26: Fully open access | F26: =INDEX('Pricing rules'!$B$4:$B$6,MATCH(E26,'Pricing rules'!$A$4:$A$6,0)) | G26: =ROUND(F26*(1-'Pricing rules'!$B$10),0) | H26: Not available — OA only | I26: ~3.2 weeks to first decision (2021 figure) | J26: Official (IEEE notice, 2021) | K26: https://ieeexplore.ieee.org/document/9689920/ | M26: APC US$2,160 confirmed by ComSoc for 2026.
A27: Signal, Image & Speech Processing | B27: IEEE Transactions on Signal Processing | C27: TSP | D27: Transactions | E27: Hybrid | F27: =INDEX('Pricing rules'!$B$4:$B$6,MATCH(E27,'Pricing rules'!$A$4:$A$6,0)) | G27: =ROUND(F27*(1-'Pricing rules'!$B$10),0) | H27: Free (overlength page charges may apply) | I27: 3–5 months to first decision | J27: Third-party estimate | K27: https://manusights.com/blog/ieee-transactions-on-signal-processing-submission-process
A28: Signal, Image & Speech Processing | B28: IEEE Signal Processing Letters | C28: SPL | D28: Letters | E28: Hybrid | F28: =INDEX('Pricing rules'!$B$4:$B$6,MATCH(E28,'Pricing rules'!$A$4:$A$6,0)) | G28: =ROUND(F28*(1-'Pricing rules'!$B$10),0) | H28: Free (overlength page charges may apply) | I28: ~1.3 months first review round | J28: Crowd-sourced (SciRev) | K28: https://scirev.org/journal/ieee-signal-processing-letters/
A29: Signal, Image & Speech Processing | B29: IEEE Journal of Selected Topics in Signal Processing | C29: JSTSP | D29: Journal | E29: Hybrid | F29: =INDEX('Pricing rules'!$B$4:$B$6,MATCH(E29,'Pricing rules'!$A$4:$A$6,0)) | G29: =ROUND(F29*(1-'Pricing rules'!$B$10),0) | H29: Free (overlength page charges may apply) | I29: 4–8 months (varies by special issue) | J29: Third-party estimate | K29: https://manusights.com/blog/average-review-times-100-journals-2026 | M29: Special-issue driven.
A30: Signal, Image & Speech Processing | B30: IEEE Transactions on Image Processing | C30: TIP | D30: Transactions | E30: Hybrid | F30: =INDEX('Pricing rules'!$B$4:$B$6,MATCH(E30,'Pricing rules'!$A$4:$A$6,0)) | G30: =ROUND(F30*(1-'Pricing rules'!$B$10),0) | H30: Free (overlength page charges may apply) | I30: Not published
A31: Signal, Image & Speech Processing | B31: IEEE/ACM Transactions on Audio, Speech, and Language Processing | C31: TASLP | D31: Transactions | E31: Hybrid | F31: =INDEX('Pricing rules'!$B$4:$B$6,MATCH(E31,'Pricing rules'!$A$4:$A$6,0)) | G31: =ROUND(F31*(1-'Pricing rules'!$B$10),0) | H31: Free (overlength page charges may apply) | I31: Not published
A32: Signal, Image & Speech Processing | B32: IEEE Transactions on Information Forensics and Security | C32: TIFS | D32: Transactions | E32: Hybrid | F32: =INDEX('Pricing rules'!$B$4:$B$6,MATCH(E32,'Pricing rules'!$A$4:$A$6,0)) | G32: =ROUND(F32*(1-'Pricing rules'!$B$10),0) | H32: Free (overlength page charges may apply) | I32: Not published
A33: Signal, Image & Speech Processing | B33: IEEE Transactions on Multimedia | C33: TMM | D33: Transactions | E33: Hybrid | F33: =INDEX('Pricing rules'!$B$4:$B$6,MATCH(E33,'Pricing rules'!$A$4:$A$6,0)) | G33: =ROUND(F33*(1-'Pricing rules'!$B$10),0) | H33: Free (overlength page charges may apply) | I33: Not published
A34: Signal, Image & Speech Processing | B34: IEEE Transactions on Computational Imaging | C34: TCI | D34: Transactions | E34: Hybrid | F34: =INDEX('Pricing rules'!$B$4:$B$6,MATCH(E34,'Pricing rules'!$A$4:$A$6,0)) | G34: =ROUND(F34*(1-'Pricing rules'!$B$10),0) | H34: Free (overlength page charges may apply) | I34: Not published
A35: Signal, Image & Speech Processing | B35: IEEE Transactions on Signal and Information Processing over Networks | C35: TSIPN | D35: Transactions | E35: Hybrid | F35: =INDEX('Pricing rules'!$B$4:$B$6,MATCH(E35,'Pricing rules'!$A$4:$A$6,0)) | G35: =ROUND(F35*(1-'Pricing rules'!$B$10),0) | H35: Free (overlength page charges may apply) | I35: Not published
A36: Signal, Image & Speech Processing | B36: IEEE Transactions on Circuits and Systems for Video Technology | C36: TCSVT | D36: Transactions | E36: Hybrid | F36: =INDEX('Pricing rules'!$B$4:$B$6,MATCH(E36,'Pricing rules'!$A$4:$A$6,0)) | G36: =ROUND(F36*(1-'Pricing rules'!$B$10),0) | H36: Free (overlength page charges may apply) | I36: Not published
A37: Signal, Image & Speech Processing | B37: IEEE Open Journal of Signal Processing | C37: OJSP | D37: Open journal | E37: Fully open access | F37: =INDEX('Pricing rules'!$B$4:$B$6,MATCH(E37,'Pricing rules'!$A$4:$A$6,0)) | G37: =ROUND(F37*(1-'Pricing rules'!$B$10),0) | H37: Not available — OA only | I37: Target 15 weeks to accept/reject (regular papers) | J37: Official target (IEEE SPS) | K37: https://signalprocessingsociety.org/publications-resources/ieee-open-journal-signal-processing/information-authors-ojsp | M37: APC US$2,160 (2026); no overlength charges; US$1,500 for the conference section with a promo code.
A38: AI, Computing & Software | B38: IEEE Transactions on Pattern Analysis and Machine Intelligence | C38: TPAMI | D38: Transactions | E38: Hybrid | F38: =INDEX('Pricing rules'!$B$4:$B$6,MATCH(E38,'Pricing rules'!$A$4:$A$6,0)) | G38: =ROUND(F38*(1-'Pricing rules'!$B$10),0) | H38: Free (overlength page charges may apply) | I38: Not published
A39: AI, Computing & Software | B39: IEEE Transactions on Neural Networks and Learning Systems | C39: TNNLS | D39: Transactions | E39: Hybrid | F39: =INDEX('Pricing rules'!$B$4:$B$6,MATCH(E39,'Pricing rules'!$A$4:$A$6,0)) | G39: =ROUND(F39*(1-'Pricing rules'!$B$10),0) | H39: Free (overlength page charges may apply) | I39: Not published
A40: AI, Computing & Software | B40: IEEE Transactions on Artificial Intelligence | C40: TAI | D40: Transactions | E40: Hybrid | F40: =INDEX('Pricing rules'!$B$4:$B$6,MATCH(E40,'Pricing rules'!$A$4:$A$6,0)) | G40: =ROUND(F40*(1-'Pricing rules'!$B$10),0) | H40: Free (overlength page charges may apply) | I40: ~12 weeks to first decision | J40: Official (IEEE CIS) | K40: https://cis.ieee.org/publications/ieee-transactions-on-artificial-intelligence/review-process
...

Sheet Magazines
A1: Track | B1: Journal | C1: Acronym | D1: Type | E1: OA model | F1: APC 2026 (US$) | G1: APC for society member (US$) | H1: Cost without OA | I1: Avg. time to first decision | J1: Decision-time source | K1: Source link | L1: Society | M1: Notes
A2: Aerospace, Radar & Navigation | B2: IEEE Aerospace and Electronic Systems Magazine | C2: AESM | D2: Magazine | E2: Hybrid magazine | F2: =INDEX('Pricing rules'!$B$4:$B$6,MATCH(E2,'Pricing rules'!$A$4:$A$6,0)) | G2: =ROUND(F2*(1-'Pricing rules'!$B$10),0) | H2: Free (most articles are invited) | I2: Not published | L2: AESS
A3: Communications & Networking | B3: IEEE Communications Magazine | C3: COMMAG | D3: Magazine | E3: Hybrid magazine | F3: =INDEX('Pricing rules'!$B$4:$B$6,MATCH(E3,'Pricing rules'!$A$4:$A$6,0)) | G3: =ROUND(F3*(1-'Pricing rules'!$B$10),0) | H3: Free (most articles are invited) | I3: Not published
A4: Communications & Networking | B4: IEEE Network | C4: NET | D4: Magazine | E4: Hybrid magazine | F4: =INDEX('Pricing rules'!$B$4:$B$6,MATCH(E4,'Pricing rules'!$A$4:$A$6,0)) | G4: =ROUND(F4*(1-'Pricing rules'!$B$10),0) | H4: Free (most articles are invited) | I4: Not published
A5: Communications & Networking | B5: IEEE Wireless Communications | C5: WC | D5: Magazine | E5: Hybrid magazine | F5: =INDEX('Pricing rules'!$B$4:$B$6,MATCH(E5,'Pricing rules'!$A$4:$A$6,0)) | G5: =ROUND(F5*(1-'Pricing rules'!$B$10),0) | H5: Free (most articles are invited) | I5: Not published
A6: Communications & Networking | B6: IEEE Internet of Things Magazine | C6: IoTM | D6: Magazine | E6: Hybrid magazine | F6: =INDEX('Pricing rules'!$B$4:$B$6,MATCH(E6,'Pricing rules'!$A$4:$A$6,0)) | G6: =ROUND(F6*(1-'Pricing rules'!$B$10),0) | H6: Free (most articles are invited) | I6: Not published
A7: Communications & Networking | B7: IEEE Communications Standards Magazine | C7: COMSTD | D7: Magazine | E7: Hybrid magazine | F7: =INDEX('Pricing rules'!$B$4:$B$6,MATCH(E7,'Pricing rules'!$A$4:$A$6,0)) | G7: =ROUND(F7*(1-'Pricing rules'!$B$10),0) | H7: Free (most articles are invited) | I7: Not published
A8: Communications & Networking | B8: IEEE BITS the Information Theory Magazine | C8: BITS | D8: Magazine | E8: Hybrid magazine | F8: =INDEX('Pricing rules'!$B$4:$B$6,MATCH(E8,'Pricing rules'!$A$4:$A$6,0)) | G8: =ROUND(F8*(1-'Pricing rules'!$B$10),0) | H8: Free (most articles are invited) | I8: Not published
A9: Vehicles & Transportation | B9: IEEE Vehicular Technology Magazine | C9: VTM | D9: Magazine | E9: Hybrid magazine | F9: =INDEX('Pricing rules'!$B$4:$B$6,MATCH(E9,'Pricing rules'!$A$4:$A$6,0)) | G9: =ROUND(F9*(1-'Pricing rules'!$B$10),0) | H9: Free (most articles are invited) | I9: Not published
A10: Vehicles & Transportation | B10: IEEE Intelligent Transportation Systems Magazine | C10: ITSM | D10: Magazine | E10: Hybrid magazine | F10: =INDEX('Pricing rules'!$B$4:$B$6,MATCH(E10,'Pricing rules'!$A$4:$A$6,0)) | G10: =ROUND(F10*(1-'Pricing rules'!$B$10),0) | H10: Free (most articles are invited) | I10: Not published
A11: Signal, Image & Speech Processing | B11: IEEE Signal Processing Magazine | C11: SPM | D11: Magazine | E11: Hybrid magazine | F11: =INDEX('Pricing rules'!$B$4:$B$6,MATCH(E11,'Pricing rules'!$A$4:$A$6,0)) | G11: =ROUND(F11*(1-'Pricing rules'!$B$10),0) | H11: Free (most articles are invited) | I11: Not published
A12: AI, Computing & Software | B12: IEEE Computational Intelligence Magazine | C12: CIM | D12: Magazine | E12: Hybrid magazine | F12: =INDEX('Pricing rules'!$B$4:$B$6,MATCH(E12,'Pricing rules'!$A$4:$A$6,0)) | G12: =ROUND(F12*(1-'Pricing rules'!$B$10),0) | H12: Free (most articles are invited) | I12: Not published
A13: AI, Computing & Software | B13: Computer | C13: COMPUTER | D13: Magazine | E13: Hybrid magazine | F13: =INDEX('Pricing rules'!$B$4:$B$6,MATCH(E13,'Pricing rules'!$A$4:$A$6,0)) | G13: =ROUND(F13*(1-'Pricing rules'!$B$10),0) | H13: Free (most articles are invited) | I13: Not published
A14: AI, Computing & Software | B14: IEEE Software | C14: SOFTWARE | D14: Magazine | E14: Hybrid magazine | F14: =INDEX('Pricing rules'!$B$4:$B$6,MATCH(E14,'Pricing rules'!$A$4:$A$6,0)) | G14: =ROUND(F14*(1-'Pricing rules'!$B$10),0) | H14: Free (most articles are invited) | I14: Not published
... A44: Multidisciplinary, Education & Society | B44: IEEE Engineering Management Review | C44: EMR | D44: Magazine | E44: Hybrid magazine | F44: =INDEX('Pricing rules'!$B$4:$B$6,MATCH(E44,'Pricing rules'!$A$4:$A$6,0)) | G44: =ROUND(F44*(1-'Pricing rules'!$B$10),0) | H44: Free (most articles are invited) | I44: Not published
